<?xml version='1.0'?>
<sdf version='1.5'>
  <model name='f1_renault_followline'>
    <pose>0 0 0 0 0 0</pose>
    <static>false</static>

    <link name='base_link' />


    <joint name='chassis_link_joint' type='fixed'>
      <pose>0.0 0.0 0.0 0 0 0</pose>
      <parent>base_link</parent>
      <child>chassis_link</child>
    </joint>

    <link name="chassis_link">
      <pose relative_to='base_link'>0 0 0 0 0 0</pose>
      <inertial>
          <mass>1</mass>
          <inertia>
            <ixx>1</ixx>
            <ixy>0.0</ixy>
            <iyy>1</iyy>
            <ixz>0.0</ixz>
            <iyz>0.0</iyz>
            <izz>1.0</izz>
        </inertia>
      </inertial>
      <collision name="collision">
          <pose relative_to='base_link'>0 0 0 0 0 1.5708 </pose>
          <geometry>
              <mesh>
                  <uri>model://f1_renault_followline/Renault/Car.obj</uri>
                  <scale>0.2 0.2 0.2</scale>
              </mesh>
          </geometry>
          <surface>
          <contact>
            <ode />
          </contact>
          <friction>
            <ode>
              <mu>0.0002</mu>
              <mu2>0.0002</mu2>
            </ode>
          </friction>
        </surface>
      </collision>
      <visual name="visual">
          <pose relative_to='base_link'>0 0 0 0 0 1.5708 </pose>
          <geometry>

            <mesh>
              <uri>model://f1_renault_followline/Renault/Car.obj</uri>
              <scale>0.2 0.2 0.2</scale>
          </mesh>
        </geometry>
      </visual>
    </link>

    
    <joint name='bl_axle' type='revolute'>
      <pose relative_to='chassis_link'>-0.14 -0.364 0.058 0 -0 0</pose>
      <parent>chassis_link</parent>
      <child>bl_1</child>
      <axis>
        <xyz>-1 0 0</xyz>
        <dynamics>
          <friction>0.02</friction>
        </dynamics>
      </axis>
    </joint>

    <link name='bl_1'>
      <pose relative_to='bl_axle'>0 0 0 0 -0 0</pose>
      <inertial>
        <pose>-0.0377 0 -0 0 -0 0</pose>
        <mass>2</mass>
        <inertia>
          <ixx>0.84514</ixx>
          <ixy>0</ixy>
          <ixz>0</ixz>
          <iyy>0.64514</iyy>
          <iyz>0</iyz>
          <izz>0.64514</izz>
        </inertia>
      </inertial>

      <collision name='bl_1_collision'>
        <pose relative_to='bl_axle'>0 0 0 0 1.5708 0</pose>
        <geometry>
          <cylinder>
            <radius>.06</radius>
            <length>.07</length>
          </cylinder>
        </geometry>
        <surface>
          <contact>
            <ode />
          </contact>
          <friction>
            <ode>
              <mu>0.0002</mu>
              <mu2>0.0002</mu2>
            </ode>
          </friction>
        </surface>
      </collision>
      <!--<visual name='bl_1_visual'>
        <pose>0.875 1.0136 0.1444 0 -0 0</pose>
        <geometry>
          <mesh>
            <scale>0.001 0.001 0.001</scale>
            <uri>model://f1ros2/meshes/bl_1.stl</uri>
          </mesh>
        </geometry>
      </visual>-->
      <!--  <gravity>1</gravity> -->
      <!-- <velocity_decay/> -->
      <self_collide>0</self_collide>
    </link>

    <joint name='br_axle' type='revolute'>
      <pose relative_to='chassis_link'>0.14 -0.364 0.058 0 -0 0</pose>
      <parent>chassis_link</parent>
      <child>br_1</child>
      <axis>
        <xyz>-1 0 0</xyz>
        <dynamics>
          <friction>0.02</friction>
        </dynamics>
      </axis>
    </joint>

    <link name='br_1'>
      <pose relative_to='br_axle'>0 0 0 0 -0 0</pose>
      <inertial>
        <pose>-0.0377 0 -0 0 -0 0</pose>
        <mass>2</mass>
        <inertia>
          <ixx>0.84514</ixx>
          <ixy>0</ixy>
          <ixz>0</ixz>
          <iyy>0.64514</iyy>
          <iyz>0</iyz>
          <izz>0.64514</izz>
        </inertia>
        
      </inertial>
      <collision name='br_1_collision'>
        <pose relative_to='br_axle'>0 0 0 0 1.5708 0</pose>
        <geometry>
          <cylinder>
            <radius>.06</radius>
            <length>.07</length>
          </cylinder>
        </geometry>
        <surface>
          <contact>
            <ode />
          </contact>
          <friction>
            <ode>
              <mu>0.0002</mu>
              <mu2>0.0002</mu2>
            </ode>
          </friction>
        </surface>
      </collision>
      <!--<visual name='br_1_visual'>
        <pose>-0.875 1.0136 0.1444 0 -0 0</pose>
        <geometry>
          <mesh>
            <scale>0.001 0.001 0.001</scale>
            <uri>model://f1ros2/meshes/br_1.stl</uri>
          </mesh>
        </geometry>
      </visual>-->
      <!--  <gravity>1</gravity> -->
      <!-- <velocity_decay/> -->
      <self_collide>0</self_collide>
    </link>
    
    <joint name='l_steer' type='revolute'>
      <pose relative_to='chassis_link'>-0.09 0.3 0.058 0 -0 0</pose>
      <parent>chassis_link</parent>
      <child>l_steer_1</child>
      <axis>
        <xyz>0 0 1</xyz>
        <limit>
          <lower>-0.95</lower>
          <upper>0.95</upper>
        </limit>
        <dynamics>
          <friction>0.02</friction>
        </dynamics>
      </axis>
    </joint>

    <link name='l_steer_1'>
      <pose relative_to='l_steer'>0 0 0 0 -0 0</pose>
      <inertial>
        <pose>-0.0377 0 -0 0 -0 0</pose>
        <mass>0.5</mass>
        <inertia>
            <ixx>0.1</ixx>
            <ixy>0.0</ixy>
            <iyy>0.1</iyy>
            <ixz>0.0</ixz>
            <iyz>0.0</iyz>
            <izz>0.1</izz>
        </inertia>
      </inertial>
      <!--  <gravity>1</gravity> -->
      <!-- <velocity_decay/> -->
      <self_collide>0</self_collide>
    </link>

    <joint name='fl_axle' type='revolute'>
      <pose relative_to='l_steer_1'>-0.05 0 0 0 -0 0</pose>
      <parent>l_steer_1</parent>
      <child>fl_1</child>
      <axis>
        <xyz>-1 0 0</xyz>
        <dynamics>
          <friction>0.02</friction>
        </dynamics>
      </axis>
    </joint>

    <link name='fl_1'>
      <pose relative_to='fl_axle'>0 0 0 0 -0 0</pose>
      <inertial>
        <pose>-0.0377 0 -0 0 -0 0</pose>
        <mass>0.5</mass>
        <inertia>
            <ixx>0.5</ixx>
            <ixy>0.0</ixy>
            <iyy>0.5</iyy>
            <ixz>0.0</ixz>
            <iyz>0.0</iyz>
            <izz>1.0</izz>
        </inertia>
      </inertial>
      <collision name='fl_1_collision'>
        <pose relative_to='fl_axle'>0 0 0 0 1.5708 0</pose>
        <geometry>
          <cylinder>
            <radius>.06</radius>
            <length>.07</length>
          </cylinder>
        </geometry>
        <surface>
          <contact>
            <ode />
          </contact>
          <friction>
            <ode>
              <mu>0.0002</mu>
              <mu2>0.0002</mu2>
            </ode>
          </friction>
        </surface>
      </collision>
      <!--<visual name='fl_1_visual'>
        <pose>0.875 -1.5174 0.1444 0 -0 0</pose>
        <geometry>
          <mesh>
            <scale>0.001 0.001 0.001</scale>
            <uri>model://f1ros2/meshes/fl_1.stl</uri>
          </mesh>
        </geometry>
      </visual>-->
      <!--  <gravity>1</gravity> -->
      <!-- <velocity_decay/> -->
      <self_collide>0</self_collide>
    </link>
    
    <joint name='r_steer' type='revolute'>
      <pose relative_to='chassis_link'>0.09 0.3 0.058 0 -0 0</pose>
      <parent>chassis_link</parent>
      <child>r_steer_1</child>
      <axis>
        <xyz>0 0 1</xyz>
        <limit>
          <lower>-0.95</lower>
          <upper>0.95</upper>
        </limit>
        <dynamics>
          <damping>0.01</damping>
          <friction>0.02</friction>
        </dynamics>
      </axis>
    </joint>

    <link name='r_steer_1'>
      <pose relative_to='r_steer'>0 0 0 0 -0 0</pose>
      <inertial>
        <pose>-0.0377 0 -0 0 -0 0</pose>
        <mass>0.5</mass>
        <inertia>
            <ixx>0.1</ixx>
            <ixy>0.0</ixy>
            <iyy>0.1</iyy>
            <ixz>0.0</ixz>
            <iyz>0.0</iyz>
            <izz>0.1</izz>
        </inertia>
      </inertial>
      <!--  <gravity>1</gravity> -->
      <!-- <velocity_decay/> -->
      <self_collide>0</self_collide>
    </link>
    
    <joint name='fr_axle' type='revolute'>
      <pose relative_to='r_steer_1'>0.05 0 0 0 -0 0</pose>
      <parent>r_steer_1</parent>
      <child>fr_1</child>
      <axis>
        <xyz>-1 0 0</xyz>
        <dynamics>
          <friction>0.02</friction>
        </dynamics>
      </axis>
    </joint>

    <link name='fr_1'>
      <pose relative_to='fr_axle'>0 0 0 0 -0 0</pose>
      <inertial>
        <pose>-0.0377 0 -0 0 -0 0</pose>
        <mass>0.5</mass>
        <inertia>
            <ixx>0.5</ixx>
            <ixy>0.0</ixy>
            <iyy>0.5</iyy>
            <ixz>0.0</ixz>
            <iyz>0.0</iyz>
            <izz>1.0</izz>
        </inertia>
      </inertial>
      <collision name='fr_1_collision'>
        <pose relative_to='fr_axle'>0 0 0 0 1.5708 0</pose>
        <geometry>
          <cylinder>
            <radius>.06</radius>
            <length>.07</length>
          </cylinder>
        </geometry>
        <surface>
          <contact>
            <ode />
          </contact>
          <friction>
            <ode>
              <mu>0.0002</mu>
              <mu2>0.0002</mu2>
            </ode>
          </friction>
        </surface>
      </collision>
      <!--<visual name='fr_1_visual'>
        <pose>-0.875 -1.5174 0.1444 0 -0 0</pose>
        <geometry>
          <mesh>
            <scale>0.001 0.001 0.001</scale>
            <uri>model://f1ros2/meshes/fr_1.stl</uri>
          </mesh>
        </geometry>
      </visual>-->
      <!--  <gravity>1</gravity> -->
      <!-- <velocity_decay/> -->
      <self_collide>0</self_collide>
    </link>

    <link name="steering_wheel" />

    <joint name="steering_joint" type="revolute">
      <pose>-0.002 0 0 0 0 0</pose>
      <parent>chassis_link</parent>
      <child>steering_wheel</child>
      <axis>
        <xyz>-0.964118 0.000768 0.265556</xyz>
        <limit>
          <lower>-100</lower>
          <upper>100</upper>
        </limit>
        <dynamics>
          <damping>1.0</damping>
        </dynamics>
        <use_parent_model_frame>true</use_parent_model_frame>
      </axis>
      <physics>
        <ode>
          <cfm_damping>1</cfm_damping>
        </ode>
      </physics>
    </joint>
    
    <plugin name='ackermann_drive' filename='libgazebo_ros_ackermann_drive.so'>
      <ros>
        <namespace>f1_renault_followline</namespace>
        <remapping>cmd_vel:=cmd_vel</remapping>
        <remapping>odom:=odom</remapping>
        <remapping>distance:=distance</remapping>
      </ros>
      <update_rate>100.0</update_rate>
    
      <front_left_joint>fl_axle</front_left_joint>
      <front_right_joint>fr_axle</front_right_joint>
      <rear_left_joint>bl_axle</rear_left_joint>
      <rear_right_joint>br_axle</rear_right_joint>
      <left_steering_joint>l_steer</left_steering_joint>
      <right_steering_joint>r_steer</right_steering_joint>
      <steering_wheel_joint>steering_joint</steering_wheel_joint>



      <max_steer>0.64</max_steer>


      <max_steering_angle>7.85</max_steering_angle>

      <max_speed>20</max_speed>

      <left_steering_pid_gain>800 0 1</left_steering_pid_gain>
      <left_steering_i_range>0 0</left_steering_i_range>
      <right_steering_pid_gain>800 0 1</right_steering_pid_gain>
      <right_steering_i_range>0 0</right_steering_i_range>
      <linear_velocity_pid_gain>800 0 1</linear_velocity_pid_gain>
      <linear_velocity_i_range>0 0</linear_velocity_i_range>


      <publish_odom>1</publish_odom>
      <publish_odom_tf>1</publish_odom_tf>
      <publish_wheel_tf>1</publish_wheel_tf>
      <publish_distance>1</publish_distance>

      <odometry_frame>odom</odometry_frame>
      <robot_base_frame>chassis_link</robot_base_frame>

    </plugin>
    
  </model>
</sdf>
